Workbook

Sheet Dataaccumulated
A1: Year | B1: Sales(bn) | C1: Operating Profit(mn) | D1: Cereal Sales(mn) | E1: Advt Cost(mn) | F1: Annual COGS | G1: Quarter | H1: Company Sales | I1: Operating Profit(mn) | J1: Cereal Sales(mn) | K1: COGS(mn) | L1: Pricing | M1: Volume | N1: Quaterly Ratio | O1: Cereal Operating Profit(mn) | P1: Cereal CoGS | Q1: Cereal Advt Cost
A3: 2017 | B3: 12.854 | C3: 1387 | D3: 5222 | E3: 732 | F3: 8155 | G3: Q1 | H3: 3248 | I3: 280 | J3: 1298 | K3: 2088 | L3: 1.2 | M3: -0.5 | N3: =(J3/1000)/$B$3 -> 0.10098024 | O3: =N3*I3 -> 28.274467 | P3: =N3*K3 -> 210.84674 | Q3: =N3*$E$3 -> 73.917535
G4: Q2 | H4: 3175 | I4: 385 | J4: 1305 | K4: 1950 | L4: 1 | M4: -0.8 | N4: =(J4/1000)/$B$3 -> 0.10152482 | O4: =N4*I4 -> 39.087055 | P4: =N4*K4 -> 197.97339 | Q4: =N4*$E$3 -> 74.316166
G5: Q3 | H5: 3246 | I5: 333 | J5: 1355 | K5: 2074 | L5: 0.9 | M5: -1.1 | N5: =(J5/1000)/$B$3 -> 0.10541466 | O5: =N5*I5 -> 35.103081 | P5: =N5*K5 -> 218.63 | Q5: =N5*$E$3 -> 77.163529
G6: Q4 | H6: 3185 | I6: =C3-SUM(I3:I5) -> 389 | J6: =D3-SUM(J3:J5) -> 1264 | K6: =7903-SUM(K3:K5) -> 1791 | L6: 1.3 | M6: -0.6 | N6: =(J6/1000)/$B$3 -> 0.098335149 | O6: =N6*I6 -> 38.252373 | P6: =N6*K6 -> 176.11825 | Q6: =N6*$E$3 -> 71.981329
A7: 2018 | B7: 13.547 | C7: 1706 | D7: 5203 | E7: 752 | F7: 8821 | G7: Q1 | H7: 3401 | I7: 510 | J7: 1351 | K7: 2149 | L7: 0.8 | M7: -1.5 | N7: =(J7/1000)/$B$7 -> 0.099726877 | O7: =N7*I7 -> 50.860707 | P7: =N7*K7 -> 214.31306 | Q7: =N7*$E$7 -> 74.994611
G8: Q2 | H8: 3360 | I8: 474 | J8: 1304 | K8: 2151 | L8: 1.1 | M8: -2 | N8: =(J8/1000)/$B$7 -> 0.096257474 | O8: =N8*I8 -> 45.626043 | P8: =N8*K8 -> 207.04983 | Q8: =N8*$E$7 -> 72.38562
G9: Q3 | H9: 3469 | I9: 396 | J9: 1330 | K9: 2293 | L9: 1.4 | M9: -2.3 | N9: =(J9/1000)/$B$7 -> 0.098176718 | O9: =N9*I9 -> 38.87798 | P9: =N9*K9 -> 225.11921 | Q9: =N9*$E$7 -> 73.828892
G10: Q4 | H10: 3317 | I10: =1706-I7-I8-I9 -> 326 | J10: =D7-J7-J8-J9 -> 1218 | K10: 2228 | L10: 1.6 | M10: -1.9 | N10: =(J10/1000)/$B$7 -> 0.089909205 | O10: =N10*I10 -> 29.310401 | P10: =N10*K10 -> 200.31771 | Q10: =N10*$E$7 -> 67.611722
A11: 2019 | B11: 13.578 | C11: 1401 | D11: 5029 | E11: 676 | F11: 9197 | G11: Q1 | H11: 3522 | I11: 381 | J11: 1275 | K11: 2415 | L11: 1.7 | M11: -2.5 | N11: =(J11/1000)/$B$11 -> 0.0939019 | O11: =N11*I11 -> 35.776624 | P11: =N11*K11 -> 226.77309 | Q11: =N11*$E$11 -> 63.477684
G12: Q2 | H12: 3461 | I12: 397 | J12: 1256 | K12: 2275 | L12: 2 | M12: -3 | N12: =(J12/1000)/$B$11 -> 0.092502578 | O12: =N12*I12 -> 36.723523 | P12: =N12*K12 -> 210.44336 | Q12: =N12*$E$11 -> 62.531743
G13: Q3 | H13: 3372 | I13: 263 | J13: 1280 | K13: 2372 | L13: 2.3 | M13: -2.8 | N13: =(J13/1000)/$B$11 -> 0.094270143 | O13: =N13*I13 -> 24.793048 | P13: =N13*K13 -> 223.60878 | Q13: =N13*$E$11 -> 63.726617
G14: Q4 | H14: 3223 | I14: =C11-(SUM(I11:I13)) -> 360 | J14: =D11-SUM(J11:J13) -> 1218 | K14: 2135 | L14: 2.5 | M14: -2.2 | N14: =(J14/1000)/$B$11 -> 0.089703933 | O14: =N14*I14 -> 32.293416 | P14: =N14*K14 -> 191.5179 | Q14: =N14*$E$11 -> 60.639859
A15: 2020 | B15: 13.77 | C15: 1761 | D15: 5433 | E15: 781 | F15: 9043 | G15: Q1 | H15: 3412 | I15: 459 | J15: 1554 | K15: 2268 | L15: 3.5 | M15: 5.8 | N15: =(J15/1000)/$B$15 -> 0.11285403 | O15: =N15*I15 -> 51.8 | P15: =N15*K15 -> 255.95294 | Q15: =N15*$E$15 -> 88.138998
G16: Q2 | H16: 3465 | I16: 506 | J16: 1444 | K16: 2268 | L16: 3.8 | M16: 6.2 | N16: =(J16/1000)/$B$15 -> 0.10486565 | O16: =N16*I16 -> 53.062019 | P16: =N16*K16 -> 237.83529 | Q16: =N16*$E$15 -> 81.900073
G17: Q3 | H17: 3429 | I17: 411 | J17: 1324 | K17: 2228 | L17: 4 | M17: 5.5 | N17: =(J17/1000)/$B$15 -> 0.096151053 | O17: =N17*I17 -> 39.518083 | P17: =N17*K17 -> 214.22455 | Q17: =N17*$E$15 -> 75.093972
G18: Q4 | H18: =(B15*1000)- SUM(H15:H17) -> 3464 | I18: =(C15)- SUM(I15:I17) -> 385 | J18: =(D15)- SUM(J15:J17) -> 1111 | K18: =(F15)- SUM(K15:K17) -> 2279 | L18: 4.2 | M18: 4.9 | N18: =(J18/1000)/$B$15 -> 0.080682643 | O18: =N18*I18 -> 31.062818 | P18: =N18*K18 -> 183.87574 | Q18: =N18*$E$15 -> 63.013145
A19: 2021 | B19: 14.18 | C19: 1752 | D19: 5123 | E19: 541 | F19: 7929 | G19: Q1 | H19: 3584 | I19: 472 | J19: 1374 | K19: 2418 | L19: 4.5 | M19: -1.2 | N19: =(J19/1000)/$B$19 -> 0.096897038 | O19: =N19*I19 -> 45.735402 | P19: =N19*K19 -> 234.29704 | Q19: =N19*$E$19 -> 52.421298
G20: Q2 | H20: 3555 | I20: 504 | J20: 1336 | K20: 2331 | L20: 5 | M20: -1.5 | N20: =(J20/1000)/$B$19 -> 0.094217207 | O20: =N20*I20 -> 47.485472 | P20: =N20*K20 -> 219.62031 | Q20: =N20*$E$19 -> 50.971509
G21: Q3 | H21: 3622 | I21: 447 | J21: 1313 | K21: 2457 | L21: 5.3 | M21: -2 | N21: =(J21/1000)/$B$19 -> 0.092595205 | O21: =N21*I21 -> 41.390056 | P21: =N21*K21 -> 227.50642 | Q21: =N21*$E$19 -> 50.094006
G22: Q4 | H22: =(B19*1000)- SUM(H19:H21) -> 3419 | I22: =(C19)- SUM(I19:I21) -> 329 | J22: =(D19)- SUM(J19:J21) -> 1100 | K22: =(F19)- SUM(K19:K21) -> 723 | L22: 5.5 | M22: -2.3 | N22: =(J22/1000)/$B$19 -> 0.077574048 | O22: =N22*I22 -> 25.521862 | P22: =N22*K22 -> 56.086037 | Q22: =N22*$E$19 -> 41.96756
A23: 2022 | B23: 15.32 | C23: 1635 | D23: 5280 | E23: 549 | F23: 8842 | G23: Q1 | H23: 3672 | I23: 517 | J23: 1281 | K23: 2513 | L23: 6.2 | M23: -3.5 | N23: =(J23/1000)/$B$23 -> 0.083616188 | O23: =N23*I23 -> 43.229569 | P23: =N23*K23 -> 210.12748 | Q23: =N23*$E$23 -> 45.905287
G24: Q2 | H24: 3864 | I24: 415 | J24: 1342 | K24: 2721 | L24: 6.5 | M24: -4 | N24: =(J24/1000)/$B$23 -> 0.087597911 | O24: =N24*I24 -> 36.353133 | P24: =N24*K24 -> 238.35392 | Q24: =N24*$E$23 -> 48.091253
G25: Q3 | H25: 3946 | I25: 368 | J25: 1355 | K25: 2793 | L25: 6.8 | M25: -4.2 | N25: =(J25/1000)/$B$23 -> 0.088446475 | O25: =N25*I25 -> 32.548303 | P25: =N25*K25 -> 247.03101 | Q25: =N25*$E$23 -> 48.557115
G26: Q4 | H26: =(B23*1000)- SUM(H23:H25) -> 3838 | I26: =(C23)- SUM(I23:I25) -> 335 | J26: =(D23)- SUM(J23:J25) -> 1302 | K26: =(F23)- SUM(K23:K25) -> 815 | L26: 7 | M26: -3.8 | N26: =(J26/1000)/$B$23 -> 0.084986945 | O26: =N26*I26 -> 28.470627 | P26: =N26*K26 -> 69.26436 | Q26: =N26*$E$23 -> 46.657833
A27: 2023 | B27: 13.12 | C27: 1505 | D27: 2736 | E27: 633 | F27: 8839 | G27: Q1 | H27: 4053 | I27: 346 | J27: 679 | K27: 2843 | L27: 7.2 | M27: -4.5 | N27: =(J27/1000)/$B$27 -> 0.051753049 | O27: =N27*I27 -> 17.906555 | P27: =N27*K27 -> 147.13392 | Q27: =N27*$E$27 -> 32.75968
G28: Q2 | H28: 4041 | I28: 417 | J28: 707 | K28: 2708 | L28: 6.8 | M28: -5.1 | N28: =(J28/1000)/$B$27 -> 0.053887195 | O28: =N28*I28 -> 22.47096 | P28: =N28*K28 -> 145.92652 | Q28: =N28*$E$27 -> 34.110595
G29: Q3 | H29: 3939 | I29: 414 | J29: 684 | K29: 2596 | L29: 6.5 | M29: -5.8 | N29: =(J29/1000)/$B$27 -> 0.052134146 | O29: =N29*I29 -> 21.583537 | P29: =N29*K29 -> 135.34024 | Q29: =N29*$E$27 -> 33.000915
G30: Q4 | H30: =(B27*1000)- SUM(H27:H29) -> 1087 | I30: =C27-(SUM(I27:I29)) -> 328 | J30: =D27-SUM(J27:J29) -> 666 | K30: =(F27)- SUM(K27:K29) -> 692 | L30: 6.9 | M30: -6 | N30: =(J30/1000)/$B$27 -> 0.050762195 | O30: =N30*I30 -> 16.65 | P30: =N30*K30 -> 35.127439 | Q30: =N30*$E$27 -> 32.13247
A31: 2024/Kellanova | B31: 12.75 | C31: 1873 | D31: 2700 | E31: 628 | F31: 8204 | G31: Q1 | H31: 3200 | I31: 393 | J31: 687 | K31: 2169 | N31: =(J31/1000)/$B$31 -> 0.053882353 | O31: =N31*I31 -> 21.175765 | P31: =N31*K31 -> 116.87082 | Q31: =N31*$E$27 -> 34.107529
G32: Q2 | H32: 3192 | I32: 493 | J32: 689 | K32: 2031 | N32: =(J32/1000)/$B$31 -> 0.054039216 | O32: =N32*I32 -> 26.641333 | P32: =N32*K32 -> 109.75365 | Q32: =N32*$E$27 -> 34.206824
G33: Q3 | H33: 3233 | I33: 456 | J33: 690 | K33: 2057 | N33: =(J33/1000)/$B$31 -> 0.054117647 | O33: =N33*I33 -> 24.677647 | P33: =N33*K33 -> 111.32 | Q33: =N33*$E$27 -> 34.256471
G34: Q4 | H34: =(B31*1000)-(SUM(H31:H33)) -> 3125 | I34: =C31-SUM(I31:I33) -> 531 | J34: =D31-687-689-690 -> 634 | K34: =(F31)- SUM(K31:K33) -> 1947 | N34: =(J34/1000)/$B$31 -> 0.04972549 | O34: =N34*I34 -> 26.404235 | P34: =N34*K34 -> 96.815529 | Q34: =N34*$E$27 -> 31.476235
A35: 2024 | B35: 15.46 | C35: 1982 | D35: 5408 | E35: 838 | F35: =F31+F43 -> 10119 | G35: Q1 | H35: =H31+H43 -> 3898 | I35: =I43+I31 -> 421 | J35: =J43+J31 -> 1372 | K35: =K31+K43 -> 2673 | L35: 4.2 | M35: -3.2 | N35: 1 | O35: =O31+O43 -> 49.175765 | P35: =P31+P43 -> 620.87082 | Q35: =Q31+Q43 -> 84.107529
G36: Q2 | H36: =H32+H44 -> 3864 | I36: =I44+I32 -> 540 | J36: =J44+J32 -> 1392 | K36: =K32+K44 -> 2507 | L36: 3.9 | M36: -2.8 | N36: 1 | O36: =O32+O44 -> 73.641333 | P36: =P32+P44 -> 585.75365 | Q36: =Q32+Q44 -> 82.206824
G37: Q3 | H37: =H33+H45 -> 3931 | I37: =I45+I33 -> 468 | J37: =J45+J33 -> 1370 | K37: =K33+K45 -> 2552 | L37: 3.8 | M37: -2.5 | N37: 1 | O37: =O33+O45 -> 36.677647 | P37: =P33+P45 -> 606.32 | Q37: =Q33+Q45 -> 82.256471
G38: Q4 | H38: =H34+H46 -> 3765 | I38: =I46+I34 -> 553 | J38: =J46+J34 -> 1274 | K38: =K34+K46 -> 2387 | L38: 3.8 | M38: -5.6 | N38: 1 | O38: =O34+O46 -> 48.404235 | P38: =P34+P46 -> 536.81553 | Q38: =Q34+Q46 -> 95.476235
A39: 2025 | G39: Q1
G40: Q2
G41: Q3
...

Sheet Sparklines
B1: 2017 | C1: 2018 | D1: 2019 | E1: 2020 | F1: 2021 | G1: 2022 | H1: 2023 | I1: 2024 | J1: Sparklines
A2: Sales(bn) | B2: 12.854 | C2: 13.547 | D2: 13.578 | E2: 13.77 | F2: 14.18 | G2: 15.32 | H2: 13.12 | I2: 15.46
A3: Operating Profit(mn) | B3: 1387 | C3: 1706 | D3: 1401 | E3: 1761 | F3: 1752 | G3: 1635 | H3: 1505 | I3: 1982
A4: Cereal Sales(mn) | B4: 5222 | C4: 5203 | D4: 5029 | E4: 5433 | F4: 5123 | G4: 5280 | H4: 2736 | I4: 5408
A5: Advt Cost(mn) | B5: 732 | C5: 752 | D5: 676 | E5: 781 | F5: 541 | G5: 549 | H5: 633 | I5: 838
A6: Annual COGS | B6: 8155 | C6: 8821 | D6: 9197 | E6: 9043 | F6: 7929 | G6: 8842 | H6: 8839 | I6: 10119

Sheet Descriptive
A1: Cereal sales | C1: Pricing | E1: Volume | G1: Cereal Operating Profit | I1: Cereal COGS | K1: Cereal Advertising Cost
A2: Mean | B2: 1232.3125 | C2: Mean | D2: 3.85 | E2: Mean | F2: -1.775 | G2: Mean | H2: 37.427065 | I2: Mean | J2: 240.94295 | K2: Mean | L2: 62.66994
A3: Standard Error | B3: 40.025633 | C3: Standard Error | D3: 0.3822419 | E3: Standard Error | F3: 0.56436519 | G3: Standard Error | H3: 2.1103302 | I3: Standard Error | J3: 25.404587 | K3: Standard Error | L3: 3.1326478
A4: Median | B4: 1303 | C4: Median | D4: 3.85 | E4: Median | F4: -2.3 | G4: Median | H4: 36.700585 | I4: Median | J4: 214.2688 | K4: Median | L4: 63.602151
A5: Mode | B5: 1355 | C5: Mode | D5: 3.8 | E5: Mode | F5: -1.5 | G5: Mode | H5: #N/A | I5: Mode | J5: #N/A | K5: Mode | L5: #N/A
A6: Standard Deviation | B6: 226.41917 | C6: Standard Deviation | D6: 2.1622867 | E6: Standard Deviation | F6: 3.1925316 | G6: Standard Deviation | H6: 11.93783 | I6: Standard Deviation | J6: 143.71005 | K6: Standard Deviation | L6: 17.720932
A7: Sample Variance | B7: 51265.641 | C7: Sample Variance | D7: 4.6754839 | E7: Sample Variance | F7: 10.192258 | G7: Sample Variance | H7: 142.5118 | I7: Sample Variance | J7: 20652.578 | K7: Sample Variance | L7: 314.03142
A8: Kurtosis | B8: 2.3383647 | C8: Kurtosis | D8: -1.3682438 | E8: Kurtosis | F8: 1.6600736 | G8: Kurtosis | H8: 1.3523884 | I8: Kurtosis | J8: 2.6179575 | K8: Kurtosis | L8: -0.94900955
A9: Skewness | B9: -1.7729383 | C9: Skewness | D9: 0.089903749 | E9: Skewness | F9: 1.4055068 | G9: Skewness | H9: 0.64900469 | I9: Skewness | J9: 1.7000383 | K9: Skewness | L9: -0.22310715
A10: Range | B10: 888 | C10: Range | D10: 6.4 | E10: Range | F10: 12.2 | G10: Range | H10: 56.991333 | I10: Range | J10: 585.74338 | K10: Range | L10: 63.343766
A11: Minimum | B11: 666 | C11: Minimum | D11: 0.8 | E11: Minimum | F11: -6 | G11: Minimum | H11: 16.65 | I11: Minimum | J11: 35.127439 | K11: Minimum | L11: 32.13247
A12: Maximum | B12: 1554 | C12: Maximum | D12: 7.2 | E12: Maximum | F12: 6.2 | G12: Maximum | H12: 73.641333 | I12: Maximum | J12: 620.87082 | K12: Maximum | L12: 95.476235

Sheet Cost_Smry_Pivot
A3: Row Labels | B3: Sum of CerealCoGS | C3: Sum of CerealOpertngProfit | D3: Sum of CerealAdvtCost
A4: 1 | B4: 210.84674 | C4: 28.274467 | D4: 73.917535
A5: 2 | B5: 197.97339 | C5: 39.087055 | D5: 74.316166
A6: 3 | B6: 218.63 | C6: 35.103081 | D6: 77.163529
A7: 4 | B7: 176.11825 | C7: 38.252373 | D7: 71.981329
A8: 5 | B8: 214.31306 | C8: 50.860707 | D8: 74.994611
A9: 6 | B9: 207.04983 | C9: 45.626043 | D9: 72.38562
A10: 7 | B10: 225.11921 | C10: 38.87798 | D10: 73.828892
A11: 8 | B11: 200.31771 | C11: 29.310401 | D11: 67.611722
A12: 9 | B12: 226.77309 | C12: 35.776624 | D12: 63.477684
A13: 10 | B13: 210.44336 | C13: 36.723523 | D13: 62.531743
A14: 11 | B14: 223.60878 | C14: 24.793048 | D14: 63.726617
A15: 12 | B15: 191.5179 | C15: 32.293416 | D15: 60.639859
... A35: 32 | B35: 536.81553 | C35: 48.404235 | D35: 95.476235
A36: Grand Total | B36: 7710.1745 | C36: 1197.6661 | D36: 2005.4381

Sheet KelloggSPSS_Data_Seasonality
A1: Quarter | B1: CerealSales | C1: Pricing | D1: Volume | E1: CerealOpertngProfit | F1: CerealCoGS | G1: CerealAdvtCost | H1: Healthy_Launch | I1: ZCerealOpertngProfit | J1: ZCerealAdvtCost | K1: Marketing_Index | M1: Quarter | N1: Moving Average | O1: Trend | P1: Seasonal Indices | Q1: Forecasted | R1: Q1 | S1: Q2 | T1: Q3 | U1: Q4 | V1: PredSales_Model 1 | W1: PredSales_Model 2 | X1: Coefficient (Model1) | Z1: Coefficient (Model2)
A2: 1 | B2: 1298 | C2: 1.2 | D2: -0.5 | E2: 28.274467 | F2: 210.84674 | G2: 73.917535 | H2: 0 | I2: -0.76668858 | J2: 0.63470679 | K2: -0.065990898 | M2: 42825 | P2: =B2-O2 -> 1298 | Q2: =B2-$R$3 -> 1245.1071 | V2: =Y2+($Y$3*C2)+(D2*$Y$4)+($Y$5*E2)+($Y$6*F2)+($Y$7*G2)+($Y$8*H2) -> 1282.0068 | W2: =$AA$2+($AA$3*C2)+(K2*$AA$4)+($AA$5*H2)+($AA$6*F2)+($AA$7*D2) -> 1265.2769 | X2: Constant | Y2: 790.58 | Z2: Constant | AA2: 1283.97
A3: 2 | B3: 1305 | C3: 1 | D3: -0.8 | E3: 39.087055 | F3: 197.97339 | G3: 74.316166 | H3: 0 | I3: 0.13905284 | J3: 0.6572017 | K3: 0.39812727 | M3: 42916 | P3: =B3-O3 -> 1305 | Q3: =B3-$S$3 -> 1269.9821 | R3: =AVERAGE(P6,P10,P14,P18,P22,P26,P30) -> 52.892857 | S3: =AVERAGE(P7,P11,P15,P19,P23,P27,P31) -> 35.017857 | T3: =AVERAGE(P8,P12,P16,P20,P24,P28,P32) -> 15.339286 | U3: =AVERAGE(P9,P13,P17,P21,P25,P29,P33) -> -94.678571 | V3: =Y3+($Y$3*C3)+(D3*$Y$4)+($Y$5*E3)+($Y$6*F3)+($Y$7*G3)+($Y$8*H3) -> 542.57987 | W3: =$AA$2+($AA$3*C3)+(K3*$AA$4)+($AA$5*H3)+($AA$6*F3)+($AA$7*D3) -> 1282.8879 | X3: Pricing | Y3: 30.987 | Z3: Constant | AA3: 13.619
A4: 3 | B4: 1355 | C4: 0.9 | D4: -1.1 | E4: 35.103081 | F4: 218.63 | G4: 77.163529 | H4: 0 | I4: -0.19467395 | J4: 0.81787963 | K4: 0.31160284 | M4: 43008 | P4: =B4-O4 -> 1355 | Q4: =B4-$T$3 -> 1339.6607 | V4: =Y4+($Y$3*C4)+(D4*$Y$4)+($Y$5*E4)+($Y$6*F4)+($Y$7*G4)+($Y$8*H4) -> 508.74099 | W4: =$AA$2+($AA$3*C4)+(K4*$AA$4)+($AA$5*H4)+($AA$6*F4)+($AA$7*D4) -> 1274.9524 | X4: Volume | Y4: -6.261 | Z4: Pricing | AA4: 39.49
A5: 4 | B5: 1264 | C5: 1.3 | D5: -0.6 | E5: 38.252373 | F5: 176.11825 | G5: 71.981329 | H5: 0 | I5: 0.069133784 | J5: 0.52544579 | K5: 0.29728979 | M5: 43100 | P5: =B5-O5 -> 1264 | Q5: =B5-$U$3 -> 1358.6786 | S5: A | T5: -8.996 | V5: =Y5+($Y$3*C5)+(D5*$Y$4)+($Y$5*E5)+($Y$6*F5)+($Y$7*G5)+($Y$8*H5) -> 512.87777 | W5: =$AA$2+($AA$3*C5)+(K5*$AA$4)+($AA$5*H5)+($AA$6*F5)+($AA$7*D5) -> 1286.3411 | X5: Operating Profit | Y5: 1.564 | Z5: Marketing Index | AA5: -552.9
A6: 5 | B6: 1351 | C6: 0.8 | D6: -1.5 | E6: 50.860707 | F6: 214.31306 | G6: 74.994611 | H6: 0 | I6: 1.1253001 | J6: 0.69548666 | K6: 0.91039338 | M6: 43190 | N6: =AVERAGE(B2:B5) -> 1305.5 | O6: =AVERAGE(N6:N7) -> 1312.125 | P6: =B6-O6 -> 38.875 | Q6: =B6-$R$3 -> 1298.1071 | S6: B | T6: 1386.1 | V6: =Y6+($Y$3*C6)+(D6*$Y$4)+($Y$5*E6)+($Y$6*F6)+($Y$7*G6)+($Y$8*H6) -> 526.01147 | W6: =$AA$2+($AA$3*C6)+(K6*$AA$4)+($AA$5*H6)+($AA$6*F6)+($AA$7*D6) -> 1297.9339 | X6: COGS | Y6: -0.384 | Z6: Healthy Launch | AA6: -0.154
A7: 6 | B7: 1304 | C7: 1.1 | D7: -2 | E7: 45.626043 | F7: 207.04983 | G7: 72.38562 | H7: 0 | I7: 0.68680631 | J7: 0.54826015 | K7: 0.61753323 | M7: 43281 | N7: =AVERAGE(B3:B6) -> 1318.75 | O7: =AVERAGE(N7:N8) -> 1318.625 | P7: =B7-O7 -> -14.625 | Q7: =B7-$S$3 -> 1268.9821 | V7: =Y7+($Y$3*C7)+(D7*$Y$4)+($Y$5*E7)+($Y$6*F7)+($Y$7*G7)+($Y$8*H7) -> 522.80479 | W7: =$AA$2+($AA$3*C7)+(K7*$AA$4)+($AA$5*H7)+($AA$6*F7)+($AA$7*D7) -> 1291.6136 | X7: Adv Cost | Y7: 6.6 | Z7: COGS | AA7: -0.081
A8: 7 | B8: 1330 | C8: 1.4 | D8: -2.3 | E8: 38.87798 | F8: 225.11921 | G8: 73.828892 | H8: 0 | I8: 0.12153925 | J8: 0.6297046 | K8: 0.37562192 | M8: 43373 | N8: =AVERAGE(B4:B7) -> 1318.5 | O8: =AVERAGE(N8:N9) -> 1315.375 | P8: =B8-O8 -> 14.625 | Q8: =B8-$T$3 -> 1314.6607 | V8: =Y8+($Y$3*C8)+(D8*$Y$4)+($Y$5*E8)+($Y$6*F8)+($Y$7*G8)+($Y$8*H8) -> -38.38783 | W8: =$AA$2+($AA$3*C8)+(K8*$AA$4)+($AA$5*H8)+($AA$6*F8)+($AA$7*D8) -> 1283.3879 | X8: Healthy Launch | Y8: -557.8 | Z8: Volume
A9: 8 | B9: 1218 | C9: 1.6 | D9: -1.9 | E9: 29.310401 | F9: 200.31771 | G9: 67.611722 | H9: 0 | I9: -0.67991119 | J9: 0.27886696 | K9: -0.20052212 | M9: 43465 | N9: =AVERAGE(B5:B8) -> 1312.25 | O9: =AVERAGE(N9:N10) -> 1306.5 | P9: =B9-O9 -> -88.5 | Q9: =B9-$U$3 -> 1312.6786 | V9: =Y9+($Y$3*C9)+(D9*$Y$4)+($Y$5*E9)+($Y$6*F9)+($Y$7*G9)+($Y$8*H9) -> 476.63193 | W9: =$AA$2+($AA$3*C9)+(K9*$AA$4)+($AA$5*H9)+($AA$6*F9)+($AA$7*D9) -> 1267.1468
A10: 9 | B10: 1275 | C10: 1.7 | D10: -2.5 | E10: 35.776624 | F10: 226.77309 | G10: 63.477684 | H10: 0 | I10: -0.13825305 | J10: 0.045581391 | K10: -0.046335829 | M10: 43555 | N10: =AVERAGE(B6:B9) -> 1300.75 | O10: =AVERAGE(N10:N11) -> 1291.25 | P10: =B10-O10 -> -16.25 | Q10: =B10-$R$3 -> 1222.1071 | V10: =Y10+($Y$3*C10)+(D10*$Y$4)+($Y$5*E10)+($Y$6*F10)+($Y$7*G10)+($Y$8*H10) -> 456.15689 | W10: =$AA$2+($AA$3*C10)+(K10*$AA$4)+($AA$5*H10)+($AA$6*F10)+($AA$7*D10) -> 1270.5719
A11: 10 | B11: 1256 | C11: 2 | D11: -3 | E11: 36.723523 | F11: 210.44336 | G11: 62.531743 | H11: 0 | I11: -0.058933829 | J11: -0.0077985316 | K11: -0.03336618 | M11: 43646 | N11: =AVERAGE(B7:B10) -> 1281.75 | O11: =AVERAGE(N11:N12) -> 1275.75 | P11: =B11-O11 -> -19.75 | Q11: =B11-$S$3 -> 1220.9821 | V11: =Y11+($Y$3*C11)+(D11*$Y$4)+($Y$5*E11)+($Y$6*F11)+($Y$7*G11)+($Y$8*H11) -> 470.09184 | W11: =$AA$2+($AA$3*C11)+(K11*$AA$4)+($AA$5*H11)+($AA$6*F11)+($AA$7*D11) -> 1277.7251
A12: 11 | B12: 1280 | C12: 2.3 | D12: -2.8 | E12: 24.793048 | F12: 223.60878 | G12: 63.726617 | H12: 0 | I12: -1.0583177 | J12: 0.059628739 | K12: -0.4993445 | M12: 43738 | N12: =AVERAGE(B8:B11) -> 1269.75 | O12: =AVERAGE(N12:N13) -> 1263.5 | P12: =B12-O12 -> 16.5 | Q12: =B12-$T$3 -> 1264.6607 | V12: =Y12+($Y$3*C12)+(D12*$Y$4)+($Y$5*E12)+($Y$6*F12)+($Y$7*G12)+($Y$8*H12) -> 462.30712 | W12: =$AA$2+($AA$3*C12)+(K12*$AA$4)+($AA$5*H12)+($AA$6*F12)+($AA$7*D12) -> 1261.3656
A13: 12 | B13: 1218 | C13: 2.5 | D13: -2.2 | E13: 32.293416 | F13: 191.5179 | G13: 60.639859 | H13: 0 | I13: -0.43003204 | J13: -0.11455838 | K13: -0.27229521 | M13: 43830 | N13: =AVERAGE(B9:B12) -> 1257.25 | O13: =AVERAGE(N13:N14) -> 1257.25 | P13: =B13-O13 -> -39.25 | Q13: =B13-$U$3 -> 1312.6786 | V13: =Y13+($Y$3*C13)+(D13*$Y$4)+($Y$5*E13)+($Y$6*F13)+($Y$7*G13)+($Y$8*H13) -> 468.4288 | W13: =$AA$2+($AA$3*C13)+(K13*$AA$4)+($AA$5*H13)+($AA$6*F13)+($AA$7*D13) -> 1277.949
A14: 13 | B14: 1554 | C14: 3.5 | D14: 5.8 | E14: 51.8 | F14: 255.95294 | G14: 88.138998 | H14: 0 | I14: 1.2039821 | J14: 1.4372302 | K14: 1.3206062 | M14: 43921 | N14: =AVERAGE(B10:B13) -> 1257.25 | O14: =AVERAGE(N14:N15) -> 1292.125 | P14: =B14-O14 -> 261.875 | Q14: =B14-$R$3 -> 1501.1071 | V14: =Y14+($Y$3*C14)+(D14*$Y$4)+($Y$5*E14)+($Y$6*F14)+($Y$7*G14)+($Y$8*H14) -> 636.58736 | W14: =$AA$2+($AA$3*C14)+(K14*$AA$4)+($AA$5*H14)+($AA$6*F14)+($AA$7*D14) -> 1343.9007
A15: 14 | B15: 1444 | C15: 3.8 | D15: 6.2 | E15: 53.062019 | F15: 237.83529 | G15: 81.900073 | H15: 0 | I15: 1.3096981 | J15: 1.0851649 | K15: 1.1974315 | M15: 44012 | N15: =AVERAGE(B11:B14) -> 1327 | O15: =AVERAGE(N15:N16) -> 1350.5 | P15: =B15-O15 -> 93.5 | Q15: =B15-$S$3 -> 1408.9821 | V15: =Y15+($Y$3*C15)+(D15*$Y$4)+($Y$5*E15)+($Y$6*F15)+($Y$7*G15)+($Y$8*H15) -> 611.13312 | W15: =$AA$2+($AA$3*C15)+(K15*$AA$4)+($AA$5*H15)+($AA$6*F15)+($AA$7*D15) -> 1345.8799
A16: 15 | B16: 1324 | C16: 4 | D16: 5.5 | E16: 39.518083 | F16: 214.22455 | G16: 75.093972 | H16: 0 | I16: 0.17515891 | J16: 0.70109364 | K16: 0.43812628 | M16: 44104 | N16: =AVERAGE(B12:B15) -> 1374 | O16: =AVERAGE(N16:N17) -> 1379.5 | P16: =B16-O16 -> -55.5 | Q16: =B16-$T$3 -> 1308.6607 | V16: =Y16+($Y$3*C16)+(D16*$Y$4)+($Y$5*E16)+($Y$6*F16)+($Y$7*G16)+($Y$8*H16) -> 564.67677 | W16: =$AA$2+($AA$3*C16)+(K16*$AA$4)+($AA$5*H16)+($AA$6*F16)+($AA$7*D16) -> 1322.3115
A17: 16 | B17: 1111 | C17: 4.2 | D17: 4.9 | E17: 31.062818 | F17: 183.87574 | G17: 63.013145 | H17: 0 | I17: -0.53311594 | J17: 0.019367195 | K17: -0.25687437 | M17: 44196 | N17: =AVERAGE(B13:B16) -> 1385 | O17: =AVERAGE(N17:N18) -> 1371.625 | P17: =B17-O17 -> -260.625 | Q17: =B17-$U$3 -> 1205.6786 | V17: =Y17+($Y$3*C17)+(D17*$Y$4)+($Y$5*E17)+($Y$6*F17)+($Y$7*G17)+($Y$8*H17) -> 493.32721 | W17: =$AA$2+($AA$3*C17)+(K17*$AA$4)+($AA$5*H17)+($AA$6*F17)+($AA$7*D17) -> 1302.3121
A18: 17 | B18: 1374 | C18: 4.5 | D18: -1.2 | E18: 45.735402 | F18: 234.29704 | G18: 52.421298 | H18: 0 | I18: 0.69596704 | J18: -0.5783354 | K18: 0.05881582 | M18: 44286 | N18: =AVERAGE(B14:B17) -> 1358.25 | O18: =AVERAGE(N18:N19) -> 1335.75 | P18: =B18-O18 -> 38.25 | Q18: =B18-$R$3 -> 1321.1071 | V18: =Y18+($Y$3*C18)+(D18*$Y$4)+($Y$5*E18)+($Y$6*F18)+($Y$7*G18)+($Y$8*H18) -> 474.49537 | W18: =$AA$2+($AA$3*C18)+(K18*$AA$4)+($AA$5*H18)+($AA$6*F18)+($AA$7*D18) -> 1311.5936
A19: 18 | B19: 1336 | C19: 5 | D19: -1.5 | E19: 47.485472 | F19: 219.62031 | G19: 50.971509 | H19: 0 | I19: 0.84256575 | J19: -0.6601476 | K19: 0.091209074 | M19: 44377 | N19: =AVERAGE(B15:B18) -> 1313.25 | O19: =AVERAGE(N19:N20) -> 1299.75 | P19: =B19-O19 -> 36.25 | Q19: =B19-$S$3 -> 1300.9821 | V19: =Y19+($Y$3*C19)+(D19*$Y$4)+($Y$5*E19)+($Y$6*F19)+($Y$7*G19)+($Y$8*H19) -> 490.67154 | W19: =$AA$2+($AA$3*C19)+(K19*$AA$4)+($AA$5*H19)+($AA$6*F19)+($AA$7*D19) -> 1321.9668
A20: 19 | B20: 1313 | C20: 5.3 | D20: -2 | E20: 41.390056 | F20: 227.50642 | G20: 50.094006 | H20: 0 | I20: 0.33196911 | J20: -0.70966551 | K20: -0.1888482 | M20: 44469 | N20: =AVERAGE(B16:B19) -> 1286.25 | O20: =AVERAGE(N20:N21) -> 1284.875 | P20: =B20-O20 -> 28.125 | Q20: =B20-$T$3 -> 1297.6607 | V20: =Y20+($Y$3*C20)+(D20*$Y$4)+($Y$5*E20)+($Y$6*F20)+($Y$7*G20)+($Y$8*H20) -> 484.74512 | W20: =$AA$2+($AA$3*C20)+(K20*$AA$4)+($AA$5*H20)+($AA$6*F20)+($AA$7*D20) -> 1313.8191
A21: 20 | B21: 1100 | C21: 5.5 | D21: -2.3 | E21: 25.521862 | F21: 56.086037 | G21: 41.96756 | H21: 0 | I21: -0.99726694 | J21: -1.1682444 | K21: -1.0827557 | M21: 44561 | N21: =AVERAGE(B17:B20) -> 1283.5 | O21: =AVERAGE(N21:N22) -> 1282.125 | P21: =B21-O21 -> -182.125 | Q21: =B21-$U$3 -> 1194.6786 | V21: =Y21+($Y$3*C21)+(D21*$Y$4)+($Y$5*E21)+($Y$6*F21)+($Y$7*G21)+($Y$8*H21) -> 480.19385 | W21: =$AA$2+($AA$3*C21)+(K21*$AA$4)+($AA$5*H21)+($AA$6*F21)+($AA$7*D21) -> 1307.6655
A22: 21 | B22: 1281 | C22: 6.2 | D22: -3.5 | E22: 43.229569 | F22: 210.12748 | G22: 45.905287 | H22: 0 | I22: 0.48606016 | J22: -0.94603674 | K22: -0.22998829 | M22: 44651 | N22: =AVERAGE(B18:B21) -> 1280.75 | O22: =AVERAGE(N22:N23) -> 1269.125 | P22: =B22-O22 -> 11.875 | Q22: =B22-$R$3 -> 1228.1071 | V22: =Y22+($Y$3*C22)+(D22*$Y$4)+($Y$5*E22)+($Y$6*F22)+($Y$7*G22)+($Y$8*H22) -> 503.92989 | W22: =$AA$2+($AA$3*C22)+(K22*$AA$4)+($AA$5*H22)+($AA$6*F22)+($AA$7*D22) -> 1327.2494
A23: 22 | B23: 1342 | C23: 6.5 | D23: -4 | E23: 36.353133 | F23: 238.35392 | G23: 48.091253 | H23: 0 | I23: -0.089960421 | J23: -0.82268171 | K23: -0.45632107 | M23: 44742 | N23: =AVERAGE(B19:B22) -> 1257.5 | O23: =AVERAGE(N23:N24) -> 1258.25 | P23: =B23-O23 -> 83.75 | Q23: =B23-$S$3 -> 1306.9821 | V23: =Y23+($Y$3*C23)+(D23*$Y$4)+($Y$5*E23)+($Y$6*F23)+($Y$7*G23)+($Y$8*H23) -> 509.19017 | W23: =$AA$2+($AA$3*C23)+(K23*$AA$4)+($AA$5*H23)+($AA$6*F23)+($AA$7*D23) -> 1318.0909
A24: 23 | B24: 1355 | C24: 6.8 | D24: -4.2 | E24: 32.548303 | F24: 247.03101 | G24: 48.557115 | H24: 0 | I24: -0.40868084 | J24: -0.79639294 | K24: -0.60253689 | M24: 44834 | N24: =AVERAGE(B20:B23) -> 1259 | O24: =AVERAGE(N24:N25) -> 1264.25 | P24: =B24-O24 -> 90.75 | Q24: =B24-$T$3 -> 1339.6607 | V24: =Y24+($Y$3*C24)+(D24*$Y$4)+($Y$5*E24)+($Y$6*F24)+($Y$7*G24)+($Y$8*H24) -> 513.5304 | W24: =$AA$2+($AA$3*C24)+(K24*$AA$4)+($AA$5*H24)+($AA$6*F24)+($AA$7*D24) -> 1315.0824
A25: 24 | B25: 1302 | C25: 7 | D25: -3.8 | E25: 28.470627 | F25: 69.26436 | G25: 46.657833 | H25: 0 | I25: -0.75025682 | J25: -0.90357026 | K25: -0.82691354 | M25: 44926 | N25: =AVERAGE(B21:B24) -> 1269.5 | O25: =AVERAGE(N25:N26) -> 1294.75 | P25: =B25-O25 -> 7.25 | Q25: =B25-$U$3 -> 1396.6786 | V25: =Y25+($Y$3*C25)+(D25*$Y$4)+($Y$5*E25)+($Y$6*F25)+($Y$7*G25)+($Y$8*H25) -> 566.57304 | W25: =$AA$2+($AA$3*C25)+(K25*$AA$4)+($AA$5*H25)+($AA$6*F25)+($AA$7*D25) -> 1336.2893
A26: 25 | B26: 679 | C26: 7.2 | D26: -4.5 | E26: 17.906555 | F26: 147.13392 | G26: 32.75968 | H26: 1 | I26: -1.6351807 | J26: -1.6878492 | K26: -1.661515 | M26: 45016 | N26: =AVERAGE(B22:B25) -> 1320 | O26: =AVERAGE(N26:N27) -> 1244.75 | P26: =B26-O26 -> -565.75 | Q26: =B26-$R$3 -> 626.10714 | V26: =Y26+($Y$3*C26)+(D26*$Y$4)+($Y$5*E26)+($Y$6*F26)+($Y$7*G26)+($Y$8*H26) -> -118.79879 | W26: =$AA$2+($AA$3*C26)+(K26*$AA$4)+($AA$5*H26)+($AA$6*F26)+($AA$7*D26) -> 741.21945
A27: 26 | B27: 707 | C27: 6.8 | D27: -5.1 | E27: 22.47096 | F27: 145.92652 | G27: 34.110595 | H27: 1 | I27: -1.2528328 | J27: -1.6116165 | K27: -1.4322246 | M27: 45107 | N27: =AVERAGE(B23:B26) -> 1169.5 | O27: =AVERAGE(N27:N28) -> 1090.125 | P27: =B27-O27 -> -383.125 | Q27: =B27-$S$3 -> 671.98214 | V27: =Y27+($Y$3*C27)+(D27*$Y$4)+($Y$5*E27)+($Y$6*F27)+($Y$7*G27)+($Y$8*H27) -> -110.91858 | W27: =$AA$2+($AA$3*C27)+(K27*$AA$4)+($AA$5*H27)+($AA$6*F27)+($AA$7*D27) -> 745.06107
A28: 27 | B28: 684 | C28: 6.5 | D28: -5.8 | E28: 21.583537 | F28: 135.34024 | G28: 33.000915 | H28: 1 | I28: -1.3271699 | J28: -1.6742362 | K28: -1.500703 | M28: 45199 | N28: =AVERAGE(B24:B27) -> 1010.75 | O28: =AVERAGE(N28:N29) -> 926.875 | P28: =B28-O28 -> -242.875 | Q28: =B28-$T$3 -> 668.66071 | V28: =Y28+($Y$3*C28)+(D28*$Y$4)+($Y$5*E28)+($Y$6*F28)+($Y$7*G28)+($Y$8*H28) -> -120.47867 | W28: =$AA$2+($AA$3*C28)+(K28*$AA$4)+($AA$5*H28)+($AA$6*F28)+($AA$7*D28) -> 739.95814
A29: 28 | B29: 666 | C29: 6.9 | D29: -6 | E29: 16.65 | F29: 35.127439 | G29: 32.13247 | H29: 1 | I29: -1.740439 | J29: -1.7232429 | K29: -1.7318409 | M29: 45291 | N29: =AVERAGE(B25:B28) -> 843 | O29: =AVERAGE(N29:N30) -> 763.5 | P29: =B29-O29 -> -97.5 | Q29: =B29-$U$3 -> 760.67857 | V29: =Y29+($Y$3*C29)+(D29*$Y$4)+($Y$5*E29)+($Y$6*F29)+($Y$7*G29)+($Y$8*H29) -> -81.797738 | W29: =$AA$2+($AA$3*C29)+(K29*$AA$4)+($AA$5*H29)+($AA$6*F29)+($AA$7*D29) -> 751.72708
A30: 29 | B30: 1372 | C30: 4.2 | D30: -3.2 | E30: 49.175765 | F30: 620.87082 | G30: 84.107529 | H30: 0 | I30: 0.98415699 | J30: 1.2097326 | K30: 1.0969448 | M30: 45382 | N30: =AVERAGE(B26:B29) -> 684 | O30: =AVERAGE(N30:N31) -> 770.625 | P30: =B30-O30 -> 601.375 | Q30: =B30-$R$3 -> 1319.1071 | V30: =Y30+($Y$3*C30)+(D30*$Y$4)+($Y$5*E30)+($Y$6*F30)+($Y$7*G30)+($Y$8*H30) -> 543.78679 | W30: =$AA$2+($AA$3*C30)+(K30*$AA$4)+($AA$5*H30)+($AA$6*F30)+($AA$7*D30) -> 1289.1332
A31: 30 | B31: 1392 | C31: 3.9 | D31: -2.8 | E31: 73.641333 | F31: 585.75365 | G31: 82.206824 | H31: 0 | I31: 3.033572 | J31: 1.102475 | K31: 2.0680235 | M31: 45473 | N31: =AVERAGE(B27:B30) -> 857.25 | O31: =AVERAGE(N31:N32) -> 942.875 | P31: =B31-O31 -> 449.125 | Q31: =B31-$S$3 -> 1356.9821 | V31: =Y31+($Y$3*C31)+(D31*$Y$4)+($Y$5*E31)+($Y$6*F31)+($Y$7*G31)+($Y$8*H31) -> 571.19078 | W31: =$AA$2+($AA$3*C31)+(K31*$AA$4)+($AA$5*H31)+($AA$6*F31)+($AA$7*D31) -> 1328.7711
A32: 31 | B32: 1370 | C32: 3.8 | D32: -2.5 | E32: 36.677647 | F32: 606.32 | G32: 82.256471 | H32: 0 | I32: -0.062776763 | J32: 1.1052766 | K32: 0.52124991 | M32: 45565 | N32: =AVERAGE(B28:B31) -> 1028.5 | O32: =AVERAGE(N32:N33) -> 1114.25 | P32: =B32-O32 -> 255.75 | Q32: =B32-$T$3 -> 1354.6607 | V32: =Y32+($Y$3*C32)+(D32*$Y$4)+($Y$5*E32)+($Y$6*F32)+($Y$7*G32)+($Y$8*H32) -> 500.83277 | W32: =$AA$2+($AA$3*C32)+(K32*$AA$4)+($AA$5*H32)+($AA$6*F32)+($AA$7*D32) -> 1263.1356
A33: 32 | B33: 1274 | C33: 3.8 | D33: -5.6 | E33: 48.404235 | F33: 536.81553 | G33: 95.476235 | H33: 0 | I33: 0.91952804 | J33: 1.8512737 | K33: 1.3854009 | M33: 45657 | N33: =AVERAGE(B29:B32) -> 1200 | O33: =AVERAGE(N33:N34) -> 1276 | P33: =B33-O33 -> -2 | Q33: =B33-$U$3 -> 1368.6786 | V33: =Y33+($Y$3*C33)+(D33*$Y$4)+($Y$5*E33)+($Y$6*F33)+($Y$7*G33)+($Y$8*H33) -> 652.52241 | W33: =$AA$2+($AA$3*C33)+(K33*$AA$4)+($AA$5*H33)+($AA$6*F33)+($AA$7*D33) -> 1308.2157
A34: 33 | C34: 3.9 | D34: -5.6 | E34: 49 | F34: 520 | G34: 95.476235 | H34: 0 | N34: =AVERAGE(B30:B33) -> 1352 | O34: =AVERAGE(N34:N35) -> 1348.6667 | Q34: =O34 -> 1348.6667 | V34: =Y34+($Y$3*C34)+(D34*$Y$4)+($Y$5*E34)+($Y$6*F34)+($Y$7*G34)+($Y$8*H34) -> 663.01005 | W34: =$AA$2+($AA$3*C34)+(K34*$AA$4)+($AA$5*H34)+($AA$6*F34)+($AA$7*D34) -> 1257.4577
A35: 34 | C35: 3.8 | D35: -5.2 | E35: 51 | F35: 550 | G35: 99 | H35: 0 | N35: =AVERAGE(B31:B34) -> 1345.3333 | O35: =AVERAGE(N35:N36) -> 1333.6667 | Q35: =O35 -> 1333.6667 | V35: =Y35+($Y$3*C35)+(D35*$Y$4)+($Y$5*E35)+($Y$6*F35)+($Y$7*G35)+($Y$8*H35) -> 672.2718 | W35: =$AA$2+($AA$3*C35)+(K35*$AA$4)+($AA$5*H35)+($AA$6*F35)+($AA$7*D35) -> 1251.4434
A36: 35 | C36: 3.7 | D36: -5.1 | E36: 50 | F36: 590 | G36: 99 | H36: 0 | N36: =AVERAGE(B32:B35) -> 1322 | O36: =AVERAGE(N36:N37) -> 1298 | Q36: =O36 -> 1298 | V36: =Y36+($Y$3*C36)+(D36*$Y$4)+($Y$5*E36)+($Y$6*F36)+($Y$7*G36)+($Y$8*H36) -> 651.623 | W36: =$AA$2+($AA$3*C36)+(K36*$AA$4)+($AA$5*H36)+($AA$6*F36)+($AA$7*D36) -> 1243.9134
A37: 36 | C37: 3.8 | D37: -5 | E37: 49 | F37: 600 | G37: 99 | H37: 0 | N37: =AVERAGE(B33:B36) -> 1274 | O37: =AVERAGE(N37:N38) -> 1274 | Q37: =O37 -> 1274 | V37: =Y37+($Y$3*C37)+(D37*$Y$4)+($Y$5*E37)+($Y$6*F37)+($Y$7*G37)+($Y$8*H37) -> 648.6916 | W37: =$AA$2+($AA$3*C37)+(K37*$AA$4)+($AA$5*H37)+($AA$6*F37)+($AA$7*D37) -> 1243.7272
A38: 37
A39: 38

Sheet Forecasting_Deseasonalised
A1: Quarter | B1: CerealSales | C1: Forecast(CerealSales) | D1: Lower Confidence Bound(CerealSales) | E1: Upper Confidence Bound(CerealSales)
A2: 42825 | B2: 1298
A3: 42916 | B3: 1305
A4: 43008 | B4: 1355
A5: 43100 | B5: 1264
A6: 43190 | B6: 1351
A7: 43281 | B7: 1304
A8: 43373 | B8: 1330
A9: 43465 | B9: 1218
A10: 43555 | B10: 1275
A11: 43646 | B11: 1256
A12: 43738 | B12: 1280
A13: 43830 | B13: 1218
... A32: 45565 | B32: 1370
A33: 45657 | B33: 1274 | C33: 1274 | D33: 1274 | E33: 1274
A34: 45747 | C34: =_xlfn.FORECAST.ETS(A34,$B$2:$B$33,$A$2:$A$33,1,1) -> 1433.2841 | D34: =C34-_xlfn.FORECAST.ETS.CONFINT(A34,$B$2:$B$33,$A$2:$A$33,0.95,1,1) -> 1071.8528 | E34: =C34+_xlfn.FORECAST.ETS.CONFINT(A34,$B$2:$B$33,$A$2:$A$33,0.95,1,1) -> 1794.7154
A35: 45839 | C35: =_xlfn.FORECAST.ETS(A35,$B$2:$B$33,$A$2:$A$33,1,1) -> 1398.4894 | D35: =C35-_xlfn.FORECAST.ETS.CONFINT(A35,$B$2:$B$33,$A$2:$A$33,0.95,1,1) -> 887.60389 | E35: =C35+_xlfn.FORECAST.ETS.CONFINT(A35,$B$2:$B$33,$A$2:$A$33,0.95,1,1) -> 1909.375
A36: 45931 | C36: =_xlfn.FORECAST.ETS(A36,$B$2:$B$33,$A$2:$A$33,1,1) -> 1388.9855 | D36: =C36-_xlfn.FORECAST.ETS.CONFINT(A36,$B$2:$B$33,$A$2:$A$33,0.95,1,1) -> 763.17674 | E36: =C36+_xlfn.FORECAST.ETS.CONFINT(A36,$B$2:$B$33,$A$2:$A$33,0.95,1,1) -> 2014.7943
A37: 46022 | C37: =_xlfn.FORECAST.ETS(A37,$B$2:$B$33,$A$2:$A$33,1,1) -> 1245.0431 | D37: =C37-_xlfn.FORECAST.ETS.CONFINT(A37,$B$2:$B$33,$A$2:$A$33,0.95,1,1) -> 522.18035 | E37: =C37+_xlfn.FORECAST.ETS.CONFINT(A37,$B$2:$B$33,$A$2:$A$33,0.95,1,1) -> 1967.9059
A38: 46112 | C38: =_xlfn.FORECAST.ETS(A38,$B$2:$B$33,$A$2:$A$33,1,1) -> 1465.2949 | D38: =C38-_xlfn.FORECAST.ETS.CONFINT(A38,$B$2:$B$33,$A$2:$A$33,0.95,1,1) -> 656.78625 | E38: =C38+_xlfn.FORECAST.ETS.CONFINT(A38,$B$2:$B$33,$A$2:$A$33,0.95,1,1) -> 2273.8035
A39: 46204 | C39: =_xlfn.FORECAST.ETS(A39,$B$2:$B$33,$A$2:$A$33,1,1) -> 1394.9982 | D39: =C39-_xlfn.FORECAST.ETS.CONFINT(A39,$B$2:$B$33,$A$2:$A$33,0.95,1,1) -> 508.93736 | E39: =C39+_xlfn.FORECAST.ETS.CONFINT(A39,$B$2:$B$33,$A$2:$A$33,0.95,1,1) -> 2281.059
A40: 46296 | C40: =_xlfn.FORECAST.ETS(A40,$B$2:$B$33,$A$2:$A$33,1,1) -> 1360.0361 | D40: =C40-_xlfn.FORECAST.ETS.CONFINT(A40,$B$2:$B$33,$A$2:$A$33,0.95,1,1) -> 402.54802 | E40: =C40+_xlfn.FORECAST.ETS.CONFINT(A40,$B$2:$B$33,$A$2:$A$33,0.95,1,1) -> 2317.5243
A41: 46387 | C41: =_xlfn.FORECAST.ETS(A41,$B$2:$B$33,$A$2:$A$33,1,1) -> 1212.2788 | D41: =C41-_xlfn.FORECAST.ETS.CONFINT(A41,$B$2:$B$33,$A$2:$A$33,0.95,1,1) -> 188.2057 | E41: =C41+_xlfn.FORECAST.ETS.CONFINT(A41,$B$2:$B$33,$A$2:$A$33,0.95,1,1) -> 2236.3519
A42: 46477 | C42: =_xlfn.FORECAST.ETS(A42,$B$2:$B$33,$A$2:$A$33,1,1) -> 1371.5629 | D42: =C42-_xlfn.FORECAST.ETS.CONFINT(A42,$B$2:$B$33,$A$2:$A$33,0.95,1,1) -> 284.73559 | E42: =C42+_xlfn.FORECAST.ETS.CONFINT(A42,$B$2:$B$33,$A$2:$A$33,0.95,1,1) -> 2458.3901
A43: 46569 | C43: =_xlfn.FORECAST.ETS(A43,$B$2:$B$33,$A$2:$A$33,1,1) -> 1336.7682 | D43: =C43-_xlfn.FORECAST.ETS.CONFINT(A43,$B$2:$B$33,$A$2:$A$33,0.95,1,1) -> 190.61753 | E43: =C43+_xlfn.FORECAST.ETS.CONFINT(A43,$B$2:$B$33,$A$2:$A$33,0.95,1,1) -> 2482.9189
A44: 46661 | C44: =_xlfn.FORECAST.ETS(A44,$B$2:$B$33,$A$2:$A$33,1,1) -> 1327.2643 | D44: =C44-_xlfn.FORECAST.ETS.CONFINT(A44,$B$2:$B$33,$A$2:$A$33,0.95,1,1) -> 124.60372 | E44: =C44+_xlfn.FORECAST.ETS.CONFINT(A44,$B$2:$B$33,$A$2:$A$33,0.95,1,1) -> 2529.9248
A45: 46752 | C45: =_xlfn.FORECAST.ETS(A45,$B$2:$B$33,$A$2:$A$33,1,1) -> 1183.3219 | D45: =C45-_xlfn.FORECAST.ETS.CONFINT(A45,$B$2:$B$33,$A$2:$A$33,0.95,1,1) -> -73.414731 | E45: =C45+_xlfn.FORECAST.ETS.CONFINT(A45,$B$2:$B$33,$A$2:$A$33,0.95,1,1) -> 2440.0585
... A49: 47118 | C49: =_xlfn.FORECAST.ETS(A49,$B$2:$B$33,$A$2:$A$33,1,1) -> 1150.5576 | D49: =C49-_xlfn.FORECAST.ETS.CONFINT(A49,$B$2:$B$33,$A$2:$A$33,0.95,1,1) -> -303.40436 | E49: =C49+_xlfn.FORECAST.ETS.CONFINT(A49,$B$2:$B$33,$A$2:$A$33,0.95,1,1) -> 2604.5195

Sheet KelloggCustomers_ProductType_20
A1: Product | B1: Customer(1000's)
A2: Any Kelloggs | B2: 13498.9
A3: Kelloggs Corn Flakes | B3: 4583.1
A4: Kelloggs Crunchy Nut Flakes | B4: 3656.9
A5: Kelloggs Rice Krispies | B5: 2980
A6: Kelloggs Frosties | B6: 2598.3
A7: Kelloggs Coco Pops | B7: 2389.4
A8: Kelloggs Special K Original | B8: 1844.8
A9: Kelloggs Bran Flakes | B9: 1754.7
A10: Kelloggs Fruit 'N Fibre | B10: 1647.7
A11: Kelloggs Krave | B11: 1285.1
A12: Kelloggs All-Bran | B12: 1115.1
A13: Kelloggs Crunchy Nut Clusters | B13: 1014
... A20: Kelloggs Crunchy Nut Bites | B20: 331

Sheet CerealProduction_2023_2024
A1: Cereal production value in the United Kingdom (UK) 2003-2024
A2: Year | B2: GBP(millions)
A3: 2003 | B3: 2218
A4: 2004 | B4: 2417
A5: 2005 | B5: 1434
A6: 2006 | B6: 1507
A7: 2007 | B7: 1949
A8: 2008 | B8: 3147
A9: 2009 | B9: 2338
A10: 2010 | B10: 2267
A11: 2011 | B11: 3230
A12: 2012 | B12: 3201
A13: 2013 | B13: 3365
A14: 2014 | B14: 3439
... A24: 2024 | B24: 3510

Sheet Customers
A3: Row Labels | B3: Sum of Consumers(in 1000s)
A4: Aldi | B4: 3428.79
A5: Alpen | B5: 3663.45
A6: Asda | B6: 3885.68
A7: Big Bear | B7: 920.28
A8: Dorset | B8: 1553.64
A9: Hero | B9: 420.17
A10: Jordans | B10: 4148.67
A11: Kelloggs | B11: 37615.24
A12: Lidl | B12: 3046.63
A13: Morrisons | B13: 1194.67
A14: Nestle | B14: 19270.54
A15: Oatbix | B15: 1014.88
... A21: Grand Total | B21: 113805.55

Sheet ProductsVariety
A3: Row Labels | B3: Count of Products
A4: Kelloggs | B4: 17
A5: Nestle | B5: 11
A6: Weetabix | B6: 5
A7: Grand Total | B7: 33

Sheet Brands_Customers_2023
A1: Brands | B1: Products | C1: Consumers(in 1000s)
A2: Kelloggs | B2: Kelloggs Corn Flakes | C2: 5615.56
A3: Kelloggs | B3: Kelloggs Crunchy Nut Flakes | C3: 4700.57
A4: Kelloggs | B4: Kelloggs Rice Krispies | C4: 4421.24
A5: Kelloggs | B5: Kelloggs Coco Pops | C5: 3442.1
A6: Kelloggs | B6: Kelloggs Frosties | C6: 3318.49
A7: Kelloggs | B7: Kelloggs Special K Original | C7: 2268.25
A8: Kelloggs | B8: Kelloggs Bran Flakes | C8: 2106.73
A9: Kelloggs | B9: Kelloggs Fruit 'N Fibre | C9: 2012.49
A10: Kelloggs | B10: Kelloggs Crunchy Nut Clusters | C10: 1354.01
A11: Kelloggs | B11: Kelloggs All-Bran | C11: 1346.81
A12: Kelloggs | B12: Kelloggs Other Special K | C12: 1269.84
A13: Kelloggs | B13: Kelloggs Honey Loops | C13: 1168.78
... A61: Lidl | B61: Lidl | C61: 3046.63

Sheet Company_Cereal_Sales
A1: Year | B1: Sales(bn) | C1: Operating Profit(mn) | D1: Cereal Sales(mn) | E1: Advt Cost(mn) | F1: Annual COGS | G1: Quarter | H1: Company Sales | I1: Operating Profit(mn) | J1: Cereal Sales(mn) | K1: COGS(mn) | L1: Pricing | M1: Volume | N1: Quaterly Ratio | O1: Cereal Operating Profit(mn) | P1: Cereal CoGS | Q1: Cereal Advt Cost | R1: Predicted sales_Model1 | S1: Predicted sales_Model2
A3: 2017 | B3: 12.854 | C3: 1387 | D3: 5222 | E3: 732 | F3: 8155 | G3: 1 | H3: 3248 | I3: 280 | J3: 1298 | K3: 2088 | L3: 1.2 | M3: -0.5 | N3: =(J3/1000)/$B$3 -> 0.10098024 | O3: =N3*I3 -> 28.274467 | P3: =N3*K3 -> 210.84674 | Q3: =N3*$E$3 -> 73.917535 | R3: =KelloggSPSS_Data_Seasonality!Y2+KelloggSPSS_Data_Seasonality!Y3*L3+KelloggSPSS_Data_Seasonality!Y4*M3+KelloggSPSS_Data_Seasonality!Y5*O3+KelloggSPSS_Data_Seasonality!Y6*K3+KelloggSPSS_Data_Seasonality!Y7*Q3+KelloggSPSS_Data_Seasonality!Y8*0 -> 561.1799
G4: 2 | H4: 3175 | I4: 385 | J4: 1305 | K4: 1950 | L4: 1 | M4: -0.8 | N4: =(J4/1000)/$B$3 -> 0.10152482 | O4: =N4*I4 -> 39.087055 | P4: =N4*K4 -> 197.97339 | Q4: =N4*$E$3 -> 74.316166 | R4: =KelloggSPSS_Data_Seasonality!Y3+KelloggSPSS_Data_Seasonality!Y4*L4+KelloggSPSS_Data_Seasonality!Y5*M4+KelloggSPSS_Data_Seasonality!Y6*O4+KelloggSPSS_Data_Seasonality!Y7*K4+KelloggSPSS_Data_Seasonality!Y8*Q4+KelloggSPSS_Data_Seasonality!Y9*0 -> -28575.092
G5: 3 | H5: 3246 | I5: 333 | J5: 1355 | K5: 2074 | L5: 0.9 | M5: -1.1 | N5: =(J5/1000)/$B$3 -> 0.10541466 | O5: =N5*I5 -> 35.103081 | P5: =N5*K5 -> 218.63 | Q5: =N5*$E$3 -> 77.163529 | R5: =KelloggSPSS_Data_Seasonality!Y4+KelloggSPSS_Data_Seasonality!Y5*L5+KelloggSPSS_Data_Seasonality!Y6*M5+KelloggSPSS_Data_Seasonality!Y7*O5+KelloggSPSS_Data_Seasonality!Y8*K5+KelloggSPSS_Data_Seasonality!Y9*Q5+KelloggSPSS_Data_Seasonality!#REF!*0 -> #REF!
G6: 4 | H6: 3185 | I6: =C3-SUM(I3:I5) -> 389 | J6: =D3-SUM(J3:J5) -> 1264 | K6: =7903-SUM(K3:K5) -> 1791 | L6: 1.3 | M6: -0.6 | N6: =(J6/1000)/$B$3 -> 0.098335149 | O6: =N6*I6 -> 38.252373 | P6: =N6*K6 -> 176.11825 | Q6: =N6*$E$3 -> 71.981329 | R6: =KelloggSPSS_Data_Seasonality!Y5+KelloggSPSS_Data_Seasonality!Y6*L6+KelloggSPSS_Data_Seasonality!Y7*M6+KelloggSPSS_Data_Seasonality!Y8*O6+KelloggSPSS_Data_Seasonality!Y9*K6+KelloggSPSS_Data_Seasonality!#REF!*Q6+KelloggSPSS_Data_Seasonality!#REF!*0 -> #REF!
A7: 2018 | B7: 13.547 | C7: 1706 | D7: 5203 | E7: 752 | F7: 8821 | G7: 5 | H7: 3401 | I7: 510 | J7: 1351 | K7: 2149 | L7: 0.8 | M7: -1.5 | N7: =(J7/1000)/$B$7 -> 0.099726877 | O7: =N7*I7 -> 50.860707 | P7: =N7*K7 -> 214.31306 | Q7: =N7*$E$7 -> 74.994611 | R7: =KelloggSPSS_Data_Seasonality!Y6+KelloggSPSS_Data_Seasonality!Y7*L7+KelloggSPSS_Data_Seasonality!Y8*M7+KelloggSPSS_Data_Seasonality!Y9*O7+KelloggSPSS_Data_Seasonality!#REF!*K7+KelloggSPSS_Data_Seasonality!#REF!*Q7+KelloggSPSS_Data_Seasonality!AA2*0 -> #REF!
G8: 6 | H8: 3360 | I8: 474 | J8: 1304 | K8: 2151 | L8: 1.1 | M8: -2 | N8: =(J8/1000)/$B$7 -> 0.096257474 | O8: =N8*I8 -> 45.626043 | P8: =N8*K8 -> 207.04983 | Q8: =N8*$E$7 -> 72.38562 | R8: =KelloggSPSS_Data_Seasonality!Y7+KelloggSPSS_Data_Seasonality!Y8*L8+KelloggSPSS_Data_Seasonality!Y9*M8+KelloggSPSS_Data_Seasonality!#REF!*O8+KelloggSPSS_Data_Seasonality!#REF!*K8+KelloggSPSS_Data_Seasonality!AA2*Q8+KelloggSPSS_Data_Seasonality!#REF!*0 -> #REF!
G9: 7 | H9: 3469 | I9: 396 | J9: 1330 | K9: 2293 | L9: 1.4 | M9: -2.3 | N9: =(J9/1000)/$B$7 -> 0.098176718 | O9: =N9*I9 -> 38.87798 | P9: =N9*K9 -> 225.11921 | Q9: =N9*$E$7 -> 73.828892 | R9: =KelloggSPSS_Data_Seasonality!Y8+KelloggSPSS_Data_Seasonality!Y9*L9+KelloggSPSS_Data_Seasonality!#REF!*M9+KelloggSPSS_Data_Seasonality!#REF!*O9+KelloggSPSS_Data_Seasonality!AA2*K9+KelloggSPSS_Data_Seasonality!#REF!*Q9+KelloggSPSS_Data_Seasonality!#REF!*0 -> #REF!
G10: 8 | H10: 3317 | I10: =1706-I7-I8-I9 -> 326 | J10: =D7-J7-J8-J9 -> 1218 | K10: 2228 | L10: 1.6 | M10: -1.9 | N10: =(J10/1000)/$B$7 -> 0.089909205 | O10: =N10*I10 -> 29.310401 | P10: =N10*K10 -> 200.31771 | Q10: =N10*$E$7 -> 67.611722 | R10: =KelloggSPSS_Data_Seasonality!Y9+KelloggSPSS_Data_Seasonality!#REF!*L10+KelloggSPSS_Data_Seasonality!#REF!*M10+KelloggSPSS_Data_Seasonality!AA2*O10+KelloggSPSS_Data_Seasonality!#REF!*K10+KelloggSPSS_Data_Seasonality!#REF!*Q10+KelloggSPSS_Data_Seasonality!AA6*0 -> #REF!
A11: 2019 | B11: 13.578 | C11: 1401 | D11: 5029 | E11: 676 | F11: 9197 | G11: 9 | H11: 3522 | I11: 381 | J11: 1275 | K11: 2415 | L11: 1.7 | M11: -2.5 | N11: =(J11/1000)/$B$11 -> 0.0939019 | O11: =N11*I11 -> 35.776624 | P11: =N11*K11 -> 226.77309 | Q11: =N11*$E$11 -> 63.477684 | R11: =KelloggSPSS_Data_Seasonality!#REF!+KelloggSPSS_Data_Seasonality!#REF!*L11+KelloggSPSS_Data_Seasonality!AA2*M11+KelloggSPSS_Data_Seasonality!#REF!*O11+KelloggSPSS_Data_Seasonality!#REF!*K11+KelloggSPSS_Data_Seasonality!AA6*Q11+KelloggSPSS_Data_Seasonality!AA4*0 -> #REF!
G12: 10 | H12: 3461 | I12: 397 | J12: 1256 | K12: 2275 | L12: 2 | M12: -3 | N12: =(J12/1000)/$B$11 -> 0.092502578 | O12: =N12*I12 -> 36.723523 | P12: =N12*K12 -> 210.44336 | Q12: =N12*$E$11 -> 62.531743 | R12: =KelloggSPSS_Data_Seasonality!#REF!+KelloggSPSS_Data_Seasonality!AA2*L12+KelloggSPSS_Data_Seasonality!#REF!*M12+KelloggSPSS_Data_Seasonality!#REF!*O12+KelloggSPSS_Data_Seasonality!AA6*K12+KelloggSPSS_Data_Seasonality!AA4*Q12+KelloggSPSS_Data_Seasonality!Y17*0 -> #REF!
G13: 11 | H13: 3372 | I13: 263 | J13: 1280 | K13: 2372 | L13: 2.3 | M13: -2.8 | N13: =(J13/1000)/$B$11 -> 0.094270143 | O13: =N13*I13 -> 24.793048 | P13: =N13*K13 -> 223.60878 | Q13: =N13*$E$11 -> 63.726617 | R13: =KelloggSPSS_Data_Seasonality!AA2+KelloggSPSS_Data_Seasonality!#REF!*L13+KelloggSPSS_Data_Seasonality!#REF!*M13+KelloggSPSS_Data_Seasonality!AA6*O13+KelloggSPSS_Data_Seasonality!AA4*K13+KelloggSPSS_Data_Seasonality!Y17*Q13+KelloggSPSS_Data_Seasonality!Y18*0 -> #REF!
G14: 12 | H14: 3223 | I14: =C11-(SUM(I11:I13)) -> 360 | J14: =D11-SUM(J11:J13) -> 1218 | K14: 2135 | L14: 2.5 | M14: -2.2 | N14: =(J14/1000)/$B$11 -> 0.089703933 | O14: =N14*I14 -> 32.293416 | P14: =N14*K14 -> 191.5179 | Q14: =N14*$E$11 -> 60.639859 | R14: =KelloggSPSS_Data_Seasonality!#REF!+KelloggSPSS_Data_Seasonality!#REF!*L14+KelloggSPSS_Data_Seasonality!AA6*M14+KelloggSPSS_Data_Seasonality!AA4*O14+KelloggSPSS_Data_Seasonality!Y17*K14+KelloggSPSS_Data_Seasonality!Y18*Q14+KelloggSPSS_Data_Seasonality!Y19*0 -> #REF!
A15: 2020 | B15: 13.77 | C15: 1761 | D15: 5433 | E15: 781 | F15: 9043 | G15: 13 | H15: 3412 | I15: 459 | J15: 1554 | K15: 2268 | L15: 3.5 | M15: 5.8 | N15: =(J15/1000)/$B$15 -> 0.11285403 | O15: =N15*I15 -> 51.8 | P15: =N15*K15 -> 255.95294 | Q15: =N15*$E$15 -> 88.138998 | R15: =KelloggSPSS_Data_Seasonality!#REF!+KelloggSPSS_Data_Seasonality!AA6*L15+KelloggSPSS_Data_Seasonality!AA4*M15+KelloggSPSS_Data_Seasonality!Y17*O15+KelloggSPSS_Data_Seasonality!Y18*K15+KelloggSPSS_Data_Seasonality!Y19*Q15+KelloggSPSS_Data_Seasonality!Y20*0 -> #REF!
G16: 14 | H16: 3465 | I16: 506 | J16: 1444 | K16: 2268 | L16: 3.8 | M16: 6.2 | N16: =(J16/1000)/$B$15 -> 0.10486565 | O16: =N16*I16 -> 53.062019 | P16: =N16*K16 -> 237.83529 | Q16: =N16*$E$15 -> 81.900073 | R16: =KelloggSPSS_Data_Seasonality!AA6+KelloggSPSS_Data_Seasonality!AA4*L16+KelloggSPSS_Data_Seasonality!Y17*M16+KelloggSPSS_Data_Seasonality!Y18*O16+KelloggSPSS_Data_Seasonality!Y19*K16+KelloggSPSS_Data_Seasonality!Y20*Q16+KelloggSPSS_Data_Seasonality!Y21*0 -> 149.908
G17: 15 | H17: 3429 | I17: 411 | J17: 1324 | K17: 2228 | L17: 4 | M17: 5.5 | N17: =(J17/1000)/$B$15 -> 0.096151053 | O17: =N17*I17 -> 39.518083 | P17: =N17*K17 -> 214.22455 | Q17: =N17*$E$15 -> 75.093972 | R17: =KelloggSPSS_Data_Seasonality!AA4+KelloggSPSS_Data_Seasonality!Y17*L17+KelloggSPSS_Data_Seasonality!Y18*M17+KelloggSPSS_Data_Seasonality!Y19*O17+KelloggSPSS_Data_Seasonality!Y20*K17+KelloggSPSS_Data_Seasonality!Y21*Q17+KelloggSPSS_Data_Seasonality!Y22*0 -> 39.49
G18: 16 | H18: =(B15*1000)- SUM(H15:H17) -> 3464 | I18: =(C15)- SUM(I15:I17) -> 385 | J18: =(D15)- SUM(J15:J17) -> 1111 | K18: =(F15)- SUM(K15:K17) -> 2279 | L18: 4.2 | M18: 4.9 | N18: =(J18/1000)/$B$15 -> 0.080682643 | O18: =N18*I18 -> 31.062818 | P18: =N18*K18 -> 183.87574 | Q18: =N18*$E$15 -> 63.013145 | R18: =KelloggSPSS_Data_Seasonality!Y17+KelloggSPSS_Data_Seasonality!Y18*L18+KelloggSPSS_Data_Seasonality!Y19*M18+KelloggSPSS_Data_Seasonality!Y20*O18+KelloggSPSS_Data_Seasonality!Y21*K18+KelloggSPSS_Data_Seasonality!Y22*Q18+KelloggSPSS_Data_Seasonality!Y23*0 -> 0
A19: 2021 | B19: 14.18 | C19: 1752 | D19: 5123 | E19: 541 | F19: 7929 | G19: 17 | H19: 3584 | I19: 472 | J19: 1374 | K19: 2418 | L19: 4.5 | M19: -1.2 | N19: =(J19/1000)/$B$19 -> 0.096897038 | O19: =N19*I19 -> 45.735402 | P19: =N19*K19 -> 234.29704 | Q19: =N19*$E$19 -> 52.421298 | R19: =KelloggSPSS_Data_Seasonality!Y18+KelloggSPSS_Data_Seasonality!Y19*L19+KelloggSPSS_Data_Seasonality!Y20*M19+KelloggSPSS_Data_Seasonality!Y21*O19+KelloggSPSS_Data_Seasonality!Y22*K19+KelloggSPSS_Data_Seasonality!Y23*Q19+KelloggSPSS_Data_Seasonality!Y24*0 -> 0
G20: 18 | H20: 3555 | I20: 504 | J20: 1336 | K20: 2331 | L20: 5 | M20: -1.5 | N20: =(J20/1000)/$B$19 -> 0.094217207 | O20: =N20*I20 -> 47.485472 | P20: =N20*K20 -> 219.62031 | Q20: =N20*$E$19 -> 50.971509 | R20: =KelloggSPSS_Data_Seasonality!Y19+KelloggSPSS_Data_Seasonality!Y20*L20+KelloggSPSS_Data_Seasonality!Y21*M20+KelloggSPSS_Data_Seasonality!Y22*O20+KelloggSPSS_Data_Seasonality!Y23*K20+KelloggSPSS_Data_Seasonality!Y24*Q20+KelloggSPSS_Data_Seasonality!Y25*0 -> 0
G21: 19 | H21: 3622 | I21: 447 | J21: 1313 | K21: 2457 | L21: 5.3 | M21: -2 | N21: =(J21/1000)/$B$19 -> 0.092595205 | O21: =N21*I21 -> 41.390056 | P21: =N21*K21 -> 227.50642 | Q21: =N21*$E$19 -> 50.094006 | R21: =KelloggSPSS_Data_Seasonality!Y20+KelloggSPSS_Data_Seasonality!Y21*L21+KelloggSPSS_Data_Seasonality!Y22*M21+KelloggSPSS_Data_Seasonality!Y23*O21+KelloggSPSS_Data_Seasonality!Y24*K21+KelloggSPSS_Data_Seasonality!Y25*Q21+KelloggSPSS_Data_Seasonality!Y26*0 -> 0
G22: 20 | H22: =(B19*1000)- SUM(H19:H21) -> 3419 | I22: =(C19)- SUM(I19:I21) -> 329 | J22: =(D19)- SUM(J19:J21) -> 1100 | K22: =(F19)- SUM(K19:K21) -> 723 | L22: 5.5 | M22: -2.3 | N22: =(J22/1000)/$B$19 -> 0.077574048 | O22: =N22*I22 -> 25.521862 | P22: =N22*K22 -> 56.086037 | Q22: =N22*$E$19 -> 41.96756 | R22: =KelloggSPSS_Data_Seasonality!Y21+KelloggSPSS_Data_Seasonality!Y22*L22+KelloggSPSS_Data_Seasonality!Y23*M22+KelloggSPSS_Data_Seasonality!Y24*O22+KelloggSPSS_Data_Seasonality!Y25*K22+KelloggSPSS_Data_Seasonality!Y26*Q22+KelloggSPSS_Data_Seasonality!Y27*0 -> 0
A23: 2022 | B23: 15.32 | C23: 1635 | D23: 5280 | E23: 549 | F23: 8842 | G23: 21 | H23: 3672 | I23: 517 | J23: 1281 | K23: 2513 | L23: 6.2 | M23: -3.5 | N23: =(J23/1000)/$B$23 -> 0.083616188 | O23: =N23*I23 -> 43.229569 | P23: =N23*K23 -> 210.12748 | Q23: =N23*$E$23 -> 45.905287 | R23: =KelloggSPSS_Data_Seasonality!Y22+KelloggSPSS_Data_Seasonality!Y23*L23+KelloggSPSS_Data_Seasonality!Y24*M23+KelloggSPSS_Data_Seasonality!Y25*O23+KelloggSPSS_Data_Seasonality!Y26*K23+KelloggSPSS_Data_Seasonality!Y27*Q23+KelloggSPSS_Data_Seasonality!Y28*0 -> 0
G24: 22 | H24: 3864 | I24: 415 | J24: 1342 | K24: 2721 | L24: 6.5 | M24: -4 | N24: =(J24/1000)/$B$23 -> 0.087597911 | O24: =N24*I24 -> 36.353133 | P24: =N24*K24 -> 238.35392 | Q24: =N24*$E$23 -> 48.091253 | R24: =KelloggSPSS_Data_Seasonality!Y23+KelloggSPSS_Data_Seasonality!Y24*L24+KelloggSPSS_Data_Seasonality!Y25*M24+KelloggSPSS_Data_Seasonality!Y26*O24+KelloggSPSS_Data_Seasonality!Y27*K24+KelloggSPSS_Data_Seasonality!Y28*Q24+KelloggSPSS_Data_Seasonality!Y29*0 -> 0
G25: 23 | H25: 3946 | I25: 368 | J25: 1355 | K25: 2793 | L25: 6.8 | M25: -4.2 | N25: =(J25/1000)/$B$23 -> 0.088446475 | O25: =N25*I25 -> 32.548303 | P25: =N25*K25 -> 247.03101 | Q25: =N25*$E$23 -> 48.557115 | R25: =KelloggSPSS_Data_Seasonality!Y24+KelloggSPSS_Data_Seasonality!Y25*L25+KelloggSPSS_Data_Seasonality!Y26*M25+KelloggSPSS_Data_Seasonality!Y27*O25+KelloggSPSS_Data_Seasonality!Y28*K25+KelloggSPSS_Data_Seasonality!Y29*Q25+KelloggSPSS_Data_Seasonality!Y30*0 -> 0
G26: 24 | H26: =(B23*1000)- SUM(H23:H25) -> 3838 | I26: =(C23)- SUM(I23:I25) -> 335 | J26: =(D23)- SUM(J23:J25) -> 1302 | K26: =(F23)- SUM(K23:K25) -> 815 | L26: 7 | M26: -3.8 | N26: =(J26/1000)/$B$23 -> 0.084986945 | O26: =N26*I26 -> 28.470627 | P26: =N26*K26 -> 69.26436 | Q26: =N26*$E$23 -> 46.657833 | R26: =KelloggSPSS_Data_Seasonality!Y25+KelloggSPSS_Data_Seasonality!Y26*L26+KelloggSPSS_Data_Seasonality!Y27*M26+KelloggSPSS_Data_Seasonality!Y28*O26+KelloggSPSS_Data_Seasonality!Y29*K26+KelloggSPSS_Data_Seasonality!Y30*Q26+KelloggSPSS_Data_Seasonality!Y31*0 -> 0
A27: 2023 | B27: 13.12 | C27: 1505 | D27: 2736 | E27: 633 | F27: 8839 | G27: 25 | H27: 4053 | I27: 346 | J27: 679 | K27: 2843 | L27: 7.2 | M27: -4.5 | N27: =(J27/1000)/$B$27 -> 0.051753049 | O27: =N27*I27 -> 17.906555 | P27: =N27*K27 -> 147.13392 | Q27: =N27*$E$27 -> 32.75968 | R27: =KelloggSPSS_Data_Seasonality!Y26+KelloggSPSS_Data_Seasonality!Y27*L27+KelloggSPSS_Data_Seasonality!Y28*M27+KelloggSPSS_Data_Seasonality!Y29*O27+KelloggSPSS_Data_Seasonality!Y30*K27+KelloggSPSS_Data_Seasonality!Y31*Q27+KelloggSPSS_Data_Seasonality!Y32*0 -> 0
G28: 26 | H28: 4041 | I28: 417 | J28: 707 | K28: 2708 | L28: 6.8 | M28: -5.1 | N28: =(J28/1000)/$B$27 -> 0.053887195 | O28: =N28*I28 -> 22.47096 | P28: =N28*K28 -> 145.92652 | Q28: =N28*$E$27 -> 34.110595 | R28: =KelloggSPSS_Data_Seasonality!Y27+KelloggSPSS_Data_Seasonality!Y28*L28+KelloggSPSS_Data_Seasonality!Y29*M28+KelloggSPSS_Data_Seasonality!Y30*O28+KelloggSPSS_Data_Seasonality!Y31*K28+KelloggSPSS_Data_Seasonality!Y32*Q28+KelloggSPSS_Data_Seasonality!Y33*0 -> 0
G29: 27 | H29: 3939 | I29: 414 | J29: 684 | K29: 2596 | L29: 6.5 | M29: -5.8 | N29: =(J29/1000)/$B$27 -> 0.052134146 | O29: =N29*I29 -> 21.583537 | P29: =N29*K29 -> 135.34024 | Q29: =N29*$E$27 -> 33.000915 | R29: =KelloggSPSS_Data_Seasonality!Y28+KelloggSPSS_Data_Seasonality!Y29*L29+KelloggSPSS_Data_Seasonality!Y30*M29+KelloggSPSS_Data_Seasonality!Y31*O29+KelloggSPSS_Data_Seasonality!Y32*K29+KelloggSPSS_Data_Seasonality!Y33*Q29+KelloggSPSS_Data_Seasonality!Y34*0 -> 0
G30: 28 | H30: =(B27*1000)- SUM(H27:H29) -> 1087 | I30: =C27-(SUM(I27:I29)) -> 328 | J30: =D27-SUM(J27:J29) -> 666 | K30: =(F27)- SUM(K27:K29) -> 692 | L30: 6.9 | M30: -6 | N30: =(J30/1000)/$B$27 -> 0.050762195 | O30: =N30*I30 -> 16.65 | P30: =N30*K30 -> 35.127439 | Q30: =N30*$E$27 -> 32.13247 | R30: =KelloggSPSS_Data_Seasonality!Y29+KelloggSPSS_Data_Seasonality!Y30*L30+KelloggSPSS_Data_Seasonality!Y31*M30+KelloggSPSS_Data_Seasonality!Y32*O30+KelloggSPSS_Data_Seasonality!Y33*K30+KelloggSPSS_Data_Seasonality!Y34*Q30+KelloggSPSS_Data_Seasonality!Y35*0 -> 0
A31: 2024/Kellanova | B31: 12.75 | C31: 1873 | D31: 2700 | E31: 628 | F31: 8204 | G31: 29 | H31: 3200 | I31: 393 | J31: 687 | K31: 2169 | N31: =(J31/1000)/$B$31 -> 0.053882353 | O31: =N31*I31 -> 21.175765 | P31: =N31*K31 -> 116.87082 | Q31: =N31*$E$27 -> 34.107529 | R31: =KelloggSPSS_Data_Seasonality!Y30+KelloggSPSS_Data_Seasonality!Y31*L31+KelloggSPSS_Data_Seasonality!Y32*M31+KelloggSPSS_Data_Seasonality!Y33*O31+KelloggSPSS_Data_Seasonality!Y34*K31+KelloggSPSS_Data_Seasonality!Y35*Q31+KelloggSPSS_Data_Seasonality!Y36*0 -> 0
G32: 30 | H32: 3192 | I32: 493 | J32: 689 | K32: 2031 | N32: =(J32/1000)/$B$31 -> 0.054039216 | O32: =N32*I32 -> 26.641333 | P32: =N32*K32 -> 109.75365 | Q32: =N32*$E$27 -> 34.206824 | R32: =KelloggSPSS_Data_Seasonality!Y31+KelloggSPSS_Data_Seasonality!Y32*L32+KelloggSPSS_Data_Seasonality!Y33*M32+KelloggSPSS_Data_Seasonality!Y34*O32+KelloggSPSS_Data_Seasonality!Y35*K32+KelloggSPSS_Data_Seasonality!Y36*Q32+KelloggSPSS_Data_Seasonality!Y37*0 -> 0
G33: 31 | H33: 3233 | I33: 456 | J33: 690 | K33: 2057 | N33: =(J33/1000)/$B$31 -> 0.054117647 | O33: =N33*I33 -> 24.677647 | P33: =N33*K33 -> 111.32 | Q33: =N33*$E$27 -> 34.256471 | R33: =KelloggSPSS_Data_Seasonality!Y32+KelloggSPSS_Data_Seasonality!Y33*L33+KelloggSPSS_Data_Seasonality!Y34*M33+KelloggSPSS_Data_Seasonality!Y35*O33+KelloggSPSS_Data_Seasonality!Y36*K33+KelloggSPSS_Data_Seasonality!Y37*Q33+KelloggSPSS_Data_Seasonality!Y38*0 -> 0
G34: 32 | H34: =(B31*1000)-(SUM(H31:H33)) -> 3125 | I34: =C31-SUM(I31:I33) -> 531 | J34: =D31-687-689-690 -> 634 | K34: =(F31)- SUM(K31:K33) -> 1947 | N34: =(J34/1000)/$B$31 -> 0.04972549 | O34: =N34*I34 -> 26.404235 | P34: =N34*K34 -> 96.815529 | Q34: =N34*$E$27 -> 31.476235 | R34: =KelloggSPSS_Data_Seasonality!Y33+KelloggSPSS_Data_Seasonality!Y34*L34+KelloggSPSS_Data_Seasonality!Y35*M34+KelloggSPSS_Data_Seasonality!Y36*O34+KelloggSPSS_Data_Seasonality!Y37*K34+KelloggSPSS_Data_Seasonality!Y38*Q34+KelloggSPSS_Data_Seasonality!Y39*0 -> 0
A35: 2024 | B35: 15.46 | C35: 1982 | D35: 5408 | E35: 838 | F35: =F31+F43 -> 10119 | G35: 33 | H35: =H31+H43 -> 3898 | I35: =I43+I31 -> 421 | J35: =J43+J31 -> 1372 | K35: =K31+K43 -> 2673 | L35: 4.2 | M35: -3.2 | N35: 1 | O35: =O31+O43 -> 49.175765 | P35: =P31+P43 -> 620.87082 | Q35: =Q31+Q43 -> 84.107529 | R35: =KelloggSPSS_Data_Seasonality!Y34+KelloggSPSS_Data_Seasonality!Y35*L35+KelloggSPSS_Data_Seasonality!Y36*M35+KelloggSPSS_Data_Seasonality!Y37*O35+KelloggSPSS_Data_Seasonality!Y38*K35+KelloggSPSS_Data_Seasonality!Y39*Q35+KelloggSPSS_Data_Seasonality!Y40*0 -> 0
G36: 34 | H36: =H32+H44 -> 3864 | I36: =I44+I32 -> 540 | J36: =J44+J32 -> 1392 | K36: =K32+K44 -> 2507 | L36: 3.9 | M36: -2.8 | N36: 1 | O36: =O32+O44 -> 73.641333 | P36: =P32+P44 -> 585.75365 | Q36: =Q32+Q44 -> 82.206824 | R36: =KelloggSPSS_Data_Seasonality!Y35+KelloggSPSS_Data_Seasonality!Y36*L36+KelloggSPSS_Data_Seasonality!Y37*M36+KelloggSPSS_Data_Seasonality!Y38*O36+KelloggSPSS_Data_Seasonality!Y39*K36+KelloggSPSS_Data_Seasonality!Y40*Q36+KelloggSPSS_Data_Seasonality!Y41*0 -> 0
G37: 35 | H37: =H33+H45 -> 3931 | I37: =I45+I33 -> 468 | J37: =J45+J33 -> 1370 | K37: =K33+K45 -> 2552 | L37: 3.8 | M37: -2.5 | N37: 1 | O37: =O33+O45 -> 36.677647 | P37: =P33+P45 -> 606.32 | Q37: =Q33+Q45 -> 82.256471 | R37: =KelloggSPSS_Data_Seasonality!Y36+KelloggSPSS_Data_Seasonality!Y37*L37+KelloggSPSS_Data_Seasonality!Y38*M37+KelloggSPSS_Data_Seasonality!Y39*O37+KelloggSPSS_Data_Seasonality!Y40*K37+KelloggSPSS_Data_Seasonality!Y41*Q37+KelloggSPSS_Data_Seasonality!Y42*0 -> 0
G38: 36 | H38: =H34+H46 -> 3765 | I38: =I46+I34 -> 553 | J38: =J46+J34 -> 1274 | K38: =K34+K46 -> 2387 | L38: 3.8 | M38: -5.6 | N38: 1 | O38: =O34+O46 -> 48.404235 | P38: =P34+P46 -> 536.81553 | Q38: =Q34+Q46 -> 95.476235 | R38: =KelloggSPSS_Data_Seasonality!Y37+KelloggSPSS_Data_Seasonality!Y38*L38+KelloggSPSS_Data_Seasonality!Y39*M38+KelloggSPSS_Data_Seasonality!Y40*O38+KelloggSPSS_Data_Seasonality!Y41*K38+KelloggSPSS_Data_Seasonality!Y42*Q38+KelloggSPSS_Data_Seasonality!Y43*0 -> 0
A39: 2025 | G39: 37 | R39: =KelloggSPSS_Data_Seasonality!Y38+KelloggSPSS_Data_Seasonality!Y39*L39+KelloggSPSS_Data_Seasonality!Y40*M39+KelloggSPSS_Data_Seasonality!Y41*O39+KelloggSPSS_Data_Seasonality!Y42*K39+KelloggSPSS_Data_Seasonality!Y43*Q39+KelloggSPSS_Data_Seasonality!Y44*0 -> 0
G40: 38 | R40: =KelloggSPSS_Data_Seasonality!Y39+KelloggSPSS_Data_Seasonality!Y40*L40+KelloggSPSS_Data_Seasonality!Y41*M40+KelloggSPSS_Data_Seasonality!Y42*O40+KelloggSPSS_Data_Seasonality!Y43*K40+KelloggSPSS_Data_Seasonality!Y44*Q40+KelloggSPSS_Data_Seasonality!Y45*0 -> 0
G41: 39 | R41: =KelloggSPSS_Data_Seasonality!Y40+KelloggSPSS_Data_Seasonality!Y41*L41+KelloggSPSS_Data_Seasonality!Y42*M41+KelloggSPSS_Data_Seasonality!Y43*O41+KelloggSPSS_Data_Seasonality!Y44*K41+KelloggSPSS_Data_Seasonality!Y45*Q41+KelloggSPSS_Data_Seasonality!Y46*0 -> 0
...
